<sdf version='1.7'>
  <model name='drone_again'>
    <link name='base_footprint'>
      <inertial>
        <pose>0.001702 0.001894 0.24906 0 -0 0</pose>
        <mass>0.5</mass>
        <inertia>
          <ixx>27.393</ixx>
          <ixy>0.00020527</ixy>
          <ixz>-0.0029529</ixz>
          <iyy>28.725</iyy>
          <iyz>0.0020718</iyz>
          <izz>51.537</izz>
        </inertia>
      </inertial>
      <collision name='base_footprint_fixed_joint_lump__base_link_collision'>
        <pose>0 0 0 0 -0 0</pose>
        <geometry>
          <mesh>
            <scale>1 1 1</scale>
            <uri>file://$(find flood_pkg)/meshes/base_link.STL</uri>
          </mesh>
        </geometry>
        <surface>
          <contact>
            <ode/>
          </contact>
          <friction>
            <ode/>
          </friction>
        </surface>
      </collision>
      <visual name='base_footprint_fixed_joint_lump__base_link_visual'>
        <pose>0 0 0 0 -0 0</pose>
        <geometry>
          <mesh>
            <scale>1 1 1</scale>
            <uri>file://$(find flood_pkg)/meshes/base_link.STL</uri>
          </mesh>
        </geometry>
        <material>
          <script>
            <name>Gazebo/Black</name>
            <uri>file://media/materials/scripts/gazebo.material</uri>
          </script>
        </material>
      </visual>
      <self_collide>1</self_collide>
      <gravity>1</gravity>
      <sensor name='sensor_imu' type='imu'>
        <always_on>1</always_on>
        <visualize>1</visualize>
        <update_rate>100</update_rate>
        <imu>
          <noise>
            <type>gaussian</type>
            <rate>
              <mean>0</mean>
              <stddev>0.01</stddev>
            </rate>
            <accel>
              <mean>0</mean>
              <stddev>0.01</stddev>
            </accel>
          </noise>
        </imu>
        <plugin name='imu' filename='libgazebo_ros_imu_sensor.so'>
          <ros>
            <namespace>/simple_drone</namespace>
          </ros>
          <initial_orientation_as_reference>0</initial_orientation_as_reference>
          <frame_name>/simple_drone/base_link</frame_name>
        </plugin>
        <pose>0 0 0 0 -0 0</pose>
      </sensor>
      <sensor name='gps' type='gps'>
        <always_on>1</always_on>
        <update_rate>30</update_rate>
        <gps>
          <position_sensing>
            <horizontal>
              <noise type='gaussian'>
                <mean>0</mean>
                <stddev>0.0002</stddev>
              </noise>
            </horizontal>
            <vertical>
              <noise type='gaussian'>
                <mean>0</mean>
                <stddev>0.0002</stddev>
              </noise>
            </vertical>
          </position_sensing>
        </gps>
        <plugin name='gps' filename='libgazebo_ros_gps_sensor.so'>
          <ros>
            <namespace>/simple_drone</namespace>
            <remapping>~/out:=~/nav</remapping>
          </ros>
          <frame_name>/simple_drone/base_link</frame_name>
        </plugin>
        <pose>0 0 0 0 -0 0</pose>
      </sensor>
      <sensor name='collision_sensor' type='contact'>
        <update_rate>100</update_rate>
        <always_on>1</always_on>
        <contact>
          <collision>base_footprint_fixed_joint_lump__drone_again_collision_collision</collision>
          <topic>__default_topic__</topic>
        </contact>
        <plugin name='collision_plugin' filename='libgazebo_ros_bumper.so'>
          <ros>
            <namespace>/simple_drone</namespace>
          </ros>
          <frame_name>/simple_drone/base_link</frame_name>
        </plugin>
        <pose>0 0 0 0 -0 0</pose>
      </sensor>
      <sensor name='down_camera' type='camera'>
        <always_on>1</always_on>
        <visualize>1</visualize>
        <update_rate>15</update_rate>
        <camera>
          <horizontal_fov>1.047</horizontal_fov>
          <image>
            <width>640</width>
            <height>360</height>
            <format>R8G8B8</format>
          </image>
          <clip>
            <near>0.1</near>
            <far>100</far>
          </clip>
          <noise>
            <type>gaussian</type>
            <mean>0</mean>
            <stddev>0.01</stddev>
          </noise>
        </camera>
        <plugin name='camera_bottom' filename='libgazebo_ros_camera.so'>
          <ros>
            <namespace>/simple_drone</namespace>
          </ros>
          <frame_name>/simple_drone/bottom_cam_link</frame_name>
          <camera_name>bottom</camera_name>
          <hack_baseline>0.07</hack_baseline>
        </plugin>
        <pose>0 0 0 3.14159 1.57079 3.14159</pose>
      </sensor>
      <sensor name='front_camera' type='depth'>
        <update_rate>30</update_rate>
        <visualize>1</visualize>
        <camera>
          <horizontal_fov>2.09</horizontal_fov>
          <image>
            <width>640</width>
            <height>360</height>
            <format>R8G8B8</format>
          </image>
          <clip>
            <near>0.1</near>
            <far>100</far>
          </clip>
          <noise>
            <type>gaussian</type>
            <mean>0</mean>
            <stddev>0.01</stddev>
          </noise>
        </camera>
        <plugin name='depth_camera_controller' filename='libgazebo_ros_camera.so'>
          <ros>
            <namespace>/simple_drone</namespace>
          </ros>
          <frame_name>/simple_drone/front_cam_link</frame_name>
          <alwaysOn>1</alwaysOn>
          <updateRate>30.0</updateRate>
          <cameraName>front_depth_camera</cameraName>
          <imageTopicName>depth/image_raw</imageTopicName>
          <cameraInfoTopicName>depth/camera_info</cameraInfoTopicName>
          <hackBaseline>0.07</hackBaseline>
          <horizontal_fov>1.047</horizontal_fov>
          <imageWidth>640</imageWidth>
          <imageHeight>480</imageHeight>
          <nearClip>0.1</nearClip>
          <farClip>100.0</farClip>
        </plugin>
        <pose>0.2 0 0 0 -0 0</pose>
      </sensor>
      <sensor name='sonar' type='ray'>
        <always_on>1</always_on>
        <visualize>1</visualize>
        <update_rate>30</update_rate>
        <ray>
          <scan>
            <horizontal>
              <samples>5</samples>
              <resolution>1</resolution>
              <min_angle>-0.12</min_angle>
              <max_angle>0.12</max_angle>
            </horizontal>
            <vertical>
              <samples>5</samples>
              <resolution>1</resolution>
              <min_angle>-0.12</min_angle>
              <max_angle>0.12</max_angle>
            </vertical>
          </scan>
          <range>
            <min>0.02</min>
            <max>10</max>
            <resolution>0.01</resolution>
          </range>
          <noise>
            <type>gaussian</type>
            <mean>0</mean>
            <stddev>0.01</stddev>
          </noise>
        </ray>
        <plugin name='sonar' filename='libgazebo_ros_ray_sensor.so'>
          <ros>
            <namespace>/simple_drone</namespace>
          </ros>
          <frame_name>/simple_drone/sonar_link</frame_name>
          <output_type>sensor_msgs/Range</output_type>
          <radiation_type>ultrasound</radiation_type>
        </plugin>
        <pose>0 0 0 3.14159 1.57079 3.14159</pose>
      </sensor>
    </link>
    <joint name='fan1_joint' type='revolute'>
      <pose relative_to='base_footprint'>-0.8465 -0.84715 0.36599 0 -0 0</pose>
      <parent>base_footprint</parent>
      <child>fan1</child>
      <axis>
        <xyz>0 0 1</xyz>
        <limit>
          <lower>-1e+16</lower>
          <upper>1e+16</upper>
        </limit>
        <dynamics>
          <spring_reference>0</spring_reference>
          <spring_stiffness>0</spring_stiffness>
        </dynamics>
      </axis>
    </joint>
    <link name='fan1'>
      <pose relative_to='fan1_joint'>0 0 0 0 -0 0</pose>
      <inertial>
        <pose>-0 0 -0.000112 0 -0 0</pose>
        <mass>0.001</mass>
        <inertia>
          <ixx>0.077898</ixx>
          <ixy>0.0029518</ixy>
          <ixz>3.7948e-09</ixz>
          <iyy>0.0019155</iyy>
          <iyz>5.4443e-09</iyz>
          <izz>0.079419</izz>
        </inertia>
      </inertial>
      <collision name='fan1_collision'>
        <pose>0 0 0 0 -0 0</pose>
        <geometry>
          <mesh>
            <scale>1 1 1</scale>
            <uri>file://$(find flood_pkg)/meshes/fan1.STL</uri>
          </mesh>
        </geometry>
        <surface>
          <contact>
            <ode/>
          </contact>
          <friction>
            <ode/>
          </friction>
        </surface>
      </collision>
      <visual name='fan1_visual'>
        <pose>0 0 0 0 -0 0</pose>
        <geometry>
          <mesh>
            <scale>1 1 1</scale>
            <uri>file://$(find flood_pkg)/meshes/fan1.STL</uri>
          </mesh>
        </geometry>
        <material>
          <script>
            <name>Gazebo/Red</name>
            <uri>file://media/materials/scripts/gazebo.material</uri>
          </script>
        </material>
      </visual>
      <self_collide>1</self_collide>
      <gravity>1</gravity>
    </link>
    <joint name='fan2_joint' type='revolute'>
      <pose relative_to='base_footprint'>-0.8465 0.84991 0.36599 0 -0 0</pose>
      <parent>base_footprint</parent>
      <child>fan2</child>
      <axis>
        <xyz>0 0 1</xyz>
        <limit>
          <lower>-1e+16</lower>
          <upper>1e+16</upper>
        </limit>
        <dynamics>
          <spring_reference>0</spring_reference>
          <spring_stiffness>0</spring_stiffness>
        </dynamics>
      </axis>
    </joint>
    <link name='fan2'>
      <pose relative_to='fan2_joint'>0 0 0 0 -0 0</pose>
      <inertial>
        <pose>-0 0 -0.000112 0 -0 0</pose>
        <mass>0.001</mass>
        <inertia>
          <ixx>0.077898</ixx>
          <ixy>0.0029518</ixy>
          <ixz>3.7935e-09</ixz>
          <iyy>0.0019155</iyy>
          <iyz>5.4394e-09</iyz>
          <izz>0.079419</izz>
        </inertia>
      </inertial>
      <collision name='fan2_collision'>
        <pose>0 0 0 0 -0 0</pose>
        <geometry>
          <mesh>
            <scale>1 1 1</scale>
            <uri>file://$(find flood_pkg)/meshes/fan2.STL</uri>
          </mesh>
        </geometry>
        <surface>
          <contact>
            <ode/>
          </contact>
          <friction>
            <ode/>
          </friction>
        </surface>
      </collision>
      <visual name='fan2_visual'>
        <pose>0 0 0 0 -0 0</pose>
        <geometry>
          <mesh>
            <scale>1 1 1</scale>
            <uri>file://$(find flood_pkg)/meshes/fan2.STL</uri>
          </mesh>
        </geometry>
        <material>
          <script>
            <name>Gazebo/Red</name>
            <uri>file://media/materials/scripts/gazebo.material</uri>
          </script>
        </material>
      </visual>
      <self_collide>1</self_collide>
      <gravity>1</gravity>
    </link>
    <joint name='fan3_joint' type='revolute'>
      <pose relative_to='base_footprint'>0.85056 0.84991 0.36599 0 -0 0</pose>
      <parent>base_footprint</parent>
      <child>fan3</child>
      <axis>
        <xyz>0 0 1</xyz>
        <limit>
          <lower>-1e+16</lower>
          <upper>1e+16</upper>
        </limit>
        <dynamics>
          <spring_reference>0</spring_reference>
          <spring_stiffness>0</spring_stiffness>
        </dynamics>
      </axis>
    </joint>
    <link name='fan3'>
      <pose relative_to='fan3_joint'>0 0 0 0 -0 0</pose>
      <inertial>
        <pose>-0 0 -0.000112 0 -0 0</pose>
        <mass>0.001</mass>
        <inertia>
          <ixx>0.077898</ixx>
          <ixy>0.0029518</ixy>
          <ixz>3.7935e-09</ixz>
          <iyy>0.0019155</iyy>
          <iyz>5.4394e-09</iyz>
          <izz>0.079419</izz>
        </inertia>
      </inertial>
      <collision name='fan3_collision'>
        <pose>0 0 0 0 -0 0</pose>
        <geometry>
          <mesh>
            <scale>1 1 1</scale>
            <uri>file://$(find flood_pkg)/meshes/fan3.STL</uri>
          </mesh>
        </geometry>
        <surface>
          <contact>
            <ode/>
          </contact>
          <friction>
            <ode/>
          </friction>
        </surface>
      </collision>
      <visual name='fan3_visual'>
        <pose>0 0 0 0 -0 0</pose>
        <geometry>
          <mesh>
            <scale>1 1 1</scale>
            <uri>file://$(find flood_pkg)/meshes/fan3.STL</uri>
          </mesh>
        </geometry>
        <material>
          <script>
            <name>Gazebo/Red</name>
            <uri>file://media/materials/scripts/gazebo.material</uri>
          </script>
        </material>
      </visual>
      <self_collide>1</self_collide>
      <gravity>1</gravity>
    </link>
    <joint name='fan4_joint' type='revolute'>
      <pose relative_to='base_footprint'>0.85056 -0.84715 0.36599 0 -0 0</pose>
      <parent>base_footprint</parent>
      <child>fan4</child>
      <axis>
        <xyz>0 0 1</xyz>
        <limit>
          <lower>-1e+16</lower>
          <upper>1e+16</upper>
        </limit>
        <dynamics>
          <spring_reference>0</spring_reference>
          <spring_stiffness>0</spring_stiffness>
        </dynamics>
      </axis>
    </joint>
    <link name='fan4'>
      <pose relative_to='fan4_joint'>0 0 0 0 -0 0</pose>
      <inertial>
        <pose>-0 0 -0.000112 0 -0 0</pose>
        <mass>0.001</mass>
        <inertia>
          <ixx>0.077898</ixx>
          <ixy>0.0029518</ixy>
          <ixz>3.8019e-09</ixz>
          <iyy>0.0019155</iyy>
          <iyz>5.4639e-09</iyz>
          <izz>0.079419</izz>
        </inertia>
      </inertial>
      <collision name='fan4_collision'>
        <pose>0 0 0 0 -0 0</pose>
        <geometry>
          <mesh>
            <scale>1 1 1</scale>
            <uri>file://$(find flood_pkg)/meshes/fan4.STL</uri>
          </mesh>
        </geometry>
        <surface>
          <contact>
            <ode/>
          </contact>
          <friction>
            <ode/>
          </friction>
        </surface>
      </collision>
      <visual name='fan4_visual'>
        <pose>0 0 0 0 -0 0</pose>
        <geometry>
          <mesh>
            <scale>1 1 1</scale>
            <uri>file://$(find flood_pkg)/meshes/fan4.STL</uri>
          </mesh>
        </geometry>
        <material>
          <script>
            <name>Gazebo/Red</name>
            <uri>file://media/materials/scripts/gazebo.material</uri>
          </script>
        </material>
      </visual>
      <self_collide>1</self_collide>
      <gravity>1</gravity>
    </link>
    <static>0</static>
    <plugin name='simple_drone' filename='libplugin_drone.so'>
      <ros>
        <namespace>/simple_drone</namespace>
        <remapping>cmd_vel:=cmd_vel</remapping>
        <remapping>imu:=imu</remapping>
        <remapping>sonar:=sonar</remapping>
        <remapping>camera_front:=camera_front</remapping>
        <remapping>camera_bottom:=camera_bottom</remapping>
        <remapping>camera_front_info:=camera_front_info</remapping>
        <remapping>camera_bottom_info:=camera_bottom_info</remapping>
        <remapping>gps:=gps</remapping>
      </ros>
      <pub_odom>1</pub_odom>
      <rollpitchProportionalGain>10.0</rollpitchProportionalGain>
      <rollpitchDifferentialGain>5.0</rollpitchDifferentialGain>
      <rollpitchLimit>0.5</rollpitchLimit>
      <yawProportionalGain>2.0</yawProportionalGain>
      <yawDifferentialGain>1.0</yawDifferentialGain>
      <yawLimit>1.5</yawLimit>
      <velocityXYProportionalGain>5.0</velocityXYProportionalGain>
      <velocityXYDifferentialGain>2.3</velocityXYDifferentialGain>
      <velocityXYLimit>2</velocityXYLimit>
      <velocityZProportionalGain>5.0</velocityZProportionalGain>
      <velocityZIntegralGain>0.0</velocityZIntegralGain>
      <velocityZDifferentialGain>1.0</velocityZDifferentialGain>
      <velocityZLimit>-1</velocityZLimit>
      <positionXYProportionalGain>1.1</positionXYProportionalGain>
      <positionXYDifferentialGain>0.0</positionXYDifferentialGain>
      <positionXYIntegralGain>0.0</positionXYIntegralGain>
      <positionXYLimit>5</positionXYLimit>
      <positionZProportionalGain>1.0</positionZProportionalGain>
      <positionZDifferentialGain>0.2</positionZDifferentialGain>
      <positionZIntegralGain>0.0</positionZIntegralGain>
      <positionZLimit>-1</positionZLimit>
      <maxForce>30</maxForce>
      <motionSmallNoise>0.0</motionSmallNoise>
      <motionDriftNoise>0.0</motionDriftNoise>
      <motionDriftNoiseTime>50</motionDriftNoiseTime>
      <bodyName>base_footprint</bodyName>
      <xyzOffset>0 0 0</xyzOffset>
      <rpyOffset>0 -0 0</rpyOffset>
    </plugin>
  </model>
</sdf>
