<?xml version="1.0" ?>
<robot name="drone_again" xmlns:xacro="http://www.ros.org/wiki/xacro">
<!-- https://answers.ros.org/question/379014/passing-outside-parameters-into-urdf-file-using-xacro/ -->
  <!-- Need argument to get from launch file -->
  <xacro:arg name="params_path" default="$(find flood_pkg)/config/drone.yaml"/> 

  <!-- Need seperate property for xacro inorder processing -->
  <xacro:property name="params_path" value="$(arg params_path)"/> 

  <!-- Read in the yaml dict as mp (short for model parameters) -->
  <xacro:property name="mp" value="${xacro.load_yaml(params_path)}"/> 

  <xacro:property name="M_PI" value="3.14159265359" />


  <link name="base_footprint"/>
  <joint name="base_footprint_joint" type="fixed">
    <origin rpy="0 0 0" xyz="0 0 0"/>
    <parent link="base_footprint"/>
    <child link="base_link"/>
  </joint>

  <link name="base_link">
    <inertial>
      <origin xyz="0.0017017 0.0018936 0.24906" rpy="0 0 0" />
      <mass value="0.5" />
      <inertia ixx="27.393" ixy="0.00020527" ixz="-0.0029529" iyy="28.725" iyz="0.0020718" izz="51.537" />
    </inertial>
    <visual>
      <origin xyz="0 0 0" rpy="0 0 0" />
      <geometry>
        <mesh filename="file://$(find flood_pkg)/meshes/base_link.STL" />
      </geometry>
      <material name="Black">
        <color rgba="0 0 0 1" />
      </material>
    </visual>
    <collision>
      <origin xyz="0 0 0" rpy="0 0 0" />
      <geometry>
        <mesh filename="file://$(find flood_pkg)/meshes/base_link.STL" />
      </geometry>
    </collision>
  </link>

  <!-- Fan 1 -->
  <link name="fan1">
    <inertial>
      <origin xyz="-6.705E-09 1.085E-09 -0.00011192" rpy="0 0 0" />
      <mass value="0.001" />
      <inertia ixx="0.077898" ixy="0.0029518" ixz="3.7948E-09" iyy="0.0019155" iyz="5.4443E-09" izz="0.079419" />
    </inertial>
    <visual>
      <origin xyz="0 0 0" rpy="0 0 0" />
      <geometry>
        <mesh filename="file://$(find flood_pkg)/meshes/fan1.STL" />
      </geometry>
      <material name="Red">
        <color rgba="1 0 0 1" />
      </material>
    </visual>
    <collision>
      <origin xyz="0 0 0" rpy="0 0 0" />
      <geometry>
        <mesh filename="file://$(find flood_pkg)/meshes/fan1.STL" />
      </geometry>
    </collision>
  </link>
  <joint name="fan1_joint" type="continuous">
    <origin xyz="-0.8465 -0.84715 0.36599" rpy="0 0 0" />
    <parent link="base_link" />
    <child link="fan1" />
    <axis xyz="0 0 1"/>
    <limit effort="1.0" velocity="100.0"/>
    <dynamics damping="0.01" friction="0.0"/>
  </joint>

  <!-- Fan 2 -->
  <link name="fan2">
    <inertial>
      <origin xyz="-6.705E-09 1.085E-09 -0.00011192" rpy="0 0 0" />
      <mass value="0.001" />
      <inertia ixx="0.077898" ixy="0.0029518" ixz="3.7935E-09" iyy="0.0019155" iyz="5.4394E-09" izz="0.079419" />
    </inertial>
    <visual>
      <origin xyz="0 0 0" rpy="0 0 0" />
      <geometry>
        <mesh filename="file://$(find flood_pkg)/meshes/fan2.STL" />
      </geometry>
      <material name="Red">
        <color rgba="1 0 0 1" />
      </material>
    </visual>
    <collision>
      <origin xyz="0 0 0" rpy="0 0 0" />
      <geometry>
        <mesh filename="file://$(find flood_pkg)/meshes/fan2.STL" />
      </geometry>
    </collision>
  </link>
  <joint name="fan2_joint" type="continuous">
    <origin xyz="-0.8465 0.84991 0.36599" rpy="0 0 0" />
    <parent link="base_link" />
    <child link="fan2" />
    <axis xyz="0 0 1"/>
    <limit effort="1.0" velocity="100.0"/>
    <dynamics damping="0.01" friction="0.0"/>
  </joint>

  <!-- Fan 3 -->
  <link name="fan3">
    <inertial>
      <origin xyz="-6.705E-09 1.085E-09 -0.00011192" rpy="0 0 0" />
      <mass value="0.001" />
      <inertia ixx="0.077898" ixy="0.0029518" ixz="3.7935E-09" iyy="0.0019155" iyz="5.4394E-09" izz="0.079419" />
    </inertial>
    <visual>
      <origin xyz="0 0 0" rpy="0 0 0" />
      <geometry>
        <mesh filename="file://$(find flood_pkg)/meshes/fan3.STL" />
      </geometry>
      <material name="Red">
        <color rgba="1 0 0 1" />
      </material>
    </visual>
    <collision>
      <origin xyz="0 0 0" rpy="0 0 0" />
      <geometry>
        <mesh filename="file://$(find flood_pkg)/meshes/fan3.STL" />
      </geometry>
    </collision>
  </link>
  <joint name="fan3_joint" type="continuous">
    <origin xyz="0.85056 0.84991 0.36599" rpy="0 0 0" />
    <parent link="base_link" />
    <child link="fan3" />
    <axis xyz="0 0 1"/>
    <limit effort="1.0" velocity="100.0"/>
    <dynamics damping="0.01" friction="0.0"/>
  </joint>

  <!-- Fan 4 -->
  <link name="fan4">
    <inertial>
      <origin xyz="-6.705E-09 1.085E-09 -0.00011192" rpy="0 0 0" />
      <mass value="0.001" />
      <inertia ixx="0.077898" ixy="0.0029518" ixz="3.8019E-09" iyy="0.0019155" iyz="5.4639E-09" izz="0.079419" />
    </inertial>
    <visual>
      <origin xyz="0 0 0" rpy="0 0 0" />
      <geometry>
        <mesh filename="file://$(find flood_pkg)/meshes/fan4.STL" />
      </geometry>
      <material name="Red">
        <color rgba="1 0 0 1" />
      </material>
    </visual>
    <collision>
      <origin xyz="0 0 0" rpy="0 0 0" />
      <geometry>
        <mesh filename="file://$(find flood_pkg)/meshes/fan4.STL" />
      </geometry>
    </collision>
  </link>
  <joint name="fan4_joint" type="continuous">
    <origin xyz="0.85056 -0.84715 0.36599" rpy="0 0 0" />
    <parent link="base_link" />
    <child link="fan4" />
    <axis xyz="0 0 1"/>
    <limit effort="1.0" velocity="100.0"/>
    <dynamics damping="0.01" friction="0.0"/>
  </joint>

  <!-- Gazebo material definitions -->

  <gazebo reference="base_link">
    <material>Gazebo/Black</material>
    <selfCollide>true</selfCollide>
    <gravity>true</gravity>
  </gazebo>

  <gazebo reference="fan1">
    <material>Gazebo/Red</material>
    <selfCollide>true</selfCollide>
    <gravity>true</gravity>
  </gazebo>

  <gazebo reference="fan2">
    <material>Gazebo/Red</material>
    <selfCollide>true</selfCollide>
    <gravity>true</gravity>
  </gazebo>

  <gazebo reference="fan3">
    <material>Gazebo/Red</material>
    <selfCollide>true</selfCollide>
    <gravity>true</gravity>
  </gazebo>

  <gazebo reference="fan4">
    <material>Gazebo/Red</material>
    <selfCollide>true</selfCollide>
    <gravity>true</gravity>
  </gazebo>

  <joint name="sonar_joint" type="fixed">
    <parent link="base_link" />
    <child link="sonar_link" />
    <origin rpy="0 ${M_PI/2} 0" xyz="0 0 0"/>
  </joint>
  <link name="sonar_link"/>

  <joint name="bottom_cam_joint" type="fixed">
    <origin rpy="0 ${M_PI/2} 0" xyz="0 0 0"/>
    <parent link="base_link" />
    <child link="bottom_cam_link" />
  </joint>
  <link name="bottom_cam_link"/>


  <joint name="lidar_joint" type="fixed">
    <origin xyz="0 0 -0.1" rpy="0 0 0"/>
    <parent link="base_link"/>
    <child link="lidar_link"/>
  </joint>

  <gazebo>
    <plugin name='simple_drone' filename='libplugin_drone.so'>
      <ros>
        <namespace>${mp['namespace']}</namespace>
        <remapping>cmd_vel:=cmd_vel</remapping>
        <remapping>imu:=imu</remapping>
        <remapping>sonar:=sonar</remapping>
        <remapping>camera_front:=camera_front</remapping>
        <remapping>camera_bottom:=camera_bottom</remapping>
        <remapping>camera_front_info:=camera_front_info</remapping>
        <remapping>camera_bottom_info:=camera_bottom_info</remapping>
        <remapping>gps:=gps</remapping>
      </ros>

      <bodyName>base_link</bodyName>
      <pub_odom>true</pub_odom>
      <rollpitchProportionalGain>${mp['rollpitchProportionalGain']}</rollpitchProportionalGain>
      <rollpitchDifferentialGain>${mp['rollpitchDifferentialGain']}</rollpitchDifferentialGain>
      <rollpitchLimit>${mp['rollpitchLimit']}</rollpitchLimit>
      <yawProportionalGain>${mp['yawProportionalGain']}</yawProportionalGain>
      <yawDifferentialGain>${mp['yawDifferentialGain']}</yawDifferentialGain>
      <yawLimit>${mp['yawLimit']}</yawLimit>
      <velocityXYProportionalGain>${mp['velocityXYProportionalGain']}</velocityXYProportionalGain>
      <velocityXYDifferentialGain>${mp['velocityXYDifferentialGain']}</velocityXYDifferentialGain>
      <velocityXYLimit>${mp['velocityXYLimit']}</velocityXYLimit>
      <velocityZProportionalGain>${mp['velocityZProportionalGain']}</velocityZProportionalGain>
      <velocityZIntegralGain>${mp['velocityZIntegralGain']}</velocityZIntegralGain>
      <velocityZDifferentialGain>${mp['velocityZDifferentialGain']}</velocityZDifferentialGain>
      <velocityZLimit>${mp['velocityZLimit']}</velocityZLimit>
      <positionXYProportionalGain>${mp['positionXYProportionalGain']}</positionXYProportionalGain>
      <positionXYDifferentialGain>${mp['positionXYDifferentialGain']}</positionXYDifferentialGain>
      <positionXYIntegralGain>${mp['positionXYIntegralGain']}</positionXYIntegralGain>
      <positionXYLimit>${mp['positionXYLimit']}</positionXYLimit>
      <positionZProportionalGain>${mp['positionZProportionalGain']}</positionZProportionalGain>
      <positionZDifferentialGain>${mp['positionZDifferentialGain']}</positionZDifferentialGain>
      <positionZIntegralGain>${mp['positionZIntegralGain']}</positionZIntegralGain>
      <positionZLimit>${mp['positionZLimit']}</positionZLimit>
      <maxForce>${mp['maxForce']}</maxForce>
      <motionSmallNoise>${mp['motionSmallNoise']}</motionSmallNoise>
      <motionDriftNoise>${mp['motionDriftNoise']}</motionDriftNoise>
      <motionDriftNoiseTime>${mp['motionDriftNoiseTime']}</motionDriftNoiseTime>
    </plugin>
  </gazebo>

  <!-- Sensors -->
  <!-- IMU sensor in 100fps -->
  <gazebo reference="base_link">
    <sensor name='sensor_imu' type='imu'>
      <always_on> 1 </always_on>
      <visualize>1</visualize>
      <update_rate> 100 </update_rate>
      <pose> 0 0 0 0 0 0 </pose>
      <imu>
        <noise>
          <type>gaussian</type>
          <rate>
            <mean> 0 </mean>
            <stddev> 0.01 </stddev>
          </rate>
          <accel>
            <mean> 0 </mean>
            <stddev> 0.01 </stddev>
          </accel>
        </noise>
      </imu>
      <plugin name='imu' filename='libgazebo_ros_imu_sensor.so'>
        <ros>
          <namespace>${mp['namespace']}</namespace>
          <!-- <remapping>imu:=imu</remapping> -->
        </ros>
        <initial_orientation_as_reference>false</initial_orientation_as_reference>
        <frame_name>${mp['namespace']}/base_link</frame_name>
      </plugin>
    </sensor>
  </gazebo>


  <!-- Sonar sensor in 100fps -->
  <gazebo reference="sonar_link">
    <sensor name="sonar" type="ray">
      <always_on>1</always_on>
      <visualize>1</visualize>
      <update_rate>30</update_rate>
      <ray>
        <scan>
          <horizontal>
            <samples>5</samples>
            <resolution>1.000000</resolution>
            <min_angle>-0.12</min_angle>
            <max_angle>0.12</max_angle>
          </horizontal>
          <vertical>
            <samples>5</samples>
            <resolution>1.000000</resolution>
            <min_angle>-0.12</min_angle>
            <max_angle>0.12</max_angle>
          </vertical>
        </scan>
        <range>
          <min>0.02</min>
          <max>10</max>
          <resolution>0.01</resolution>
        </range>
        <noise>
          <type>gaussian</type>
          <mean>0.0</mean>
          <stddev>0.01</stddev>
        </noise>
      </ray>
      <plugin name="sonar" filename="libgazebo_ros_ray_sensor.so">
        <ros>
          <namespace>${mp['namespace']}</namespace>
          <!-- <remapping>~/out:=sonar</remapping> -->
        </ros>
        <frame_name>${mp['namespace']}/sonar_link</frame_name>
        <output_type>sensor_msgs/Range</output_type>
        <radiation_type>ultrasound</radiation_type>
      </plugin>
    </sensor>
  </gazebo>


  <!-- downward looking camera -->
  <gazebo reference="bottom_cam_link">
    <sensor name="down_camera" type="camera">
      <always_on>1</always_on>
      <visualize>1</visualize>
      <update_rate>15</update_rate>
      <camera>
        <horizontal_fov>1.047</horizontal_fov>
        <image>
          <width>640</width>
          <height>360</height>
          <format>R8G8B8</format>
        </image>
        <clip>
          <near>0.1</near>
          <far>100</far>
        </clip>
        <noise>
          <type>gaussian</type>
          <mean>0.0</mean>
          <stddev>0.01</stddev>
        </noise>
      </camera>
      <plugin name="camera_bottom" filename="libgazebo_ros_camera.so">
        <ros>
          <namespace>${mp['namespace']}</namespace>
          <!-- <remapping>image_raw:=camera_bottom</remapping>
          <remapping>camera_info:=camera_bottom_info</remapping> -->
        </ros>
        <frame_name>${mp['namespace']}/bottom_cam_link</frame_name>
        <camera_name>bottom</camera_name>
        <hack_baseline>0.07</hack_baseline>
      </plugin>
    </sensor>
  </gazebo>


<!-- Velodyne ending -->

  <gazebo reference="base_link">
    <sensor name="gps" type="gps">
      <always_on>1</always_on>
      <update_rate>30</update_rate>
      <gps>
        <position_sensing>
          <horizontal>
            <noise type="gaussian">
              <mean>0.0</mean>
              <stddev>2e-4</stddev>
            </noise>
          </horizontal>
          <vertical>
            <noise type="gaussian">
              <mean>0.0</mean>
              <stddev>2e-4</stddev>
            </noise>
          </vertical>
        </position_sensing>
      </gps>
      <plugin name="gps" filename="libgazebo_ros_gps_sensor.so">
        <ros>
          <namespace>${mp['namespace']}</namespace>
          <remapping>~/out:=~/nav</remapping>
        </ros>
        <frame_name>${mp['namespace']}/base_link</frame_name>
      </plugin>
    </sensor>
  </gazebo>


  <gazebo reference="base_link">
    <sensor name="collision_sensor" type="contact">
      <update_rate>100.0</update_rate>
      <always_on>true</always_on>
      <contact>
        <collision>base_footprint_fixed_joint_lump__drone_again_collision_collision</collision>
      </contact>
      <plugin name="collision_plugin" filename="libgazebo_ros_bumper.so">
        <ros>
          <namespace>${mp['namespace']}</namespace>
          <!-- <remapping>bumper_states:=bumper_states</remapping> -->
        </ros>
        <frame_name>${mp['namespace']}/base_link</frame_name>
      </plugin>
    </sensor>
  </gazebo>

  <!-- Existing lidar configuration -->
  <link name="lidar_link">
    <collision>
      <origin xyz="0 0 0" rpy="0 0 0"/>
      <geometry>
        <cylinder radius="0.0" length="0.0"/>
      </geometry>
    </collision>
    <visual>
      <origin xyz="0 0 0.06" rpy="0 0 0"/>
      <geometry>
        <cylinder radius="0.0" length="0.0"/>
      </geometry>
      <material name="blue">
        <color rgba="0 0 1 1"/>
      </material>
    </visual>
    <inertial>
      <mass value="0.1"/>
      <origin xyz="0 0 0" rpy="0 0 0"/>
      <inertia ixx="0.000016667" ixy="0" ixz="0" iyy="0.000016667" iyz="0" izz="0.000025000"/>
    </inertial>
  </link>

  <gazebo reference="lidar_link">
    <sensor name="lidar_sensor" type="ray">
      <always_on>true</always_on>
      <visualize>false</visualize>
      <update_rate>1</update_rate>
      <ray>
        <scan>
          <horizontal>
            <samples>180</samples>
            <resolution>1</resolution>
            <min_angle>-3.14159</min_angle>
            <max_angle>3.14159</max_angle>
          </horizontal>
          <vertical>
            <samples>10</samples>
            <resolution>1</resolution>
            <min_angle>0.0</min_angle>
            <max_angle>-0.261</max_angle>
          </vertical>
        </scan>
        <range>
          <min>0.10</min>
          <max>10.0</max>
        </range>
      </ray>
      <plugin name="lidar_plugin" filename="libgazebo_ros_ray_sensor.so">
        <ros>
          <namespace>${mp['namespace']}</namespace>
          <remapping>~/out:=lidar_scan</remapping>
        </ros>
        <output_type>sensor_msgs/PointCloud2</output_type>
        <frame_name>${mp['namespace']}/lidar_link</frame_name>
      </plugin>
    </sensor>
  </gazebo>

  <joint name="front_cam_joint" type="fixed">
    <origin xyz="0.85 0 0.2" rpy="0 0 0"/>
    <parent link="base_link"/>
    <child link="front_cam_link"/>
  </joint>
  <link name="front_cam_link"/>

  <!-- Add this new Gazebo plugin for the front depth camera -->
  <gazebo reference="front_cam_link">
    <sensor name="front_depth_camera" type="depth">
      <always_on>1</always_on>
      <visualize>true</visualize>
      <update_rate>30</update_rate>
      <camera>
        <horizontal_fov>1.047198</horizontal_fov>
        <image>
          <width>640</width>
          <height>480</height>
          <format>B8G8R8</format>
        </image>
        <clip>
          <near>0.05</near>
          <far>3</far>
        </clip>
      </camera>
      <plugin name="front_depth_camera_controller" filename="libgazebo_ros_camera.so">
        <ros>
          <namespace>${mp['namespace']}</namespace>
          <remapping>image_raw:=front_depth/image_raw</remapping>
          <remapping>camera_info:=front_depth/camera_info</remapping>
          <remapping>points:=front_depth/points</remapping>
        </ros>
        <camera_name>front_depth</camera_name>
        <frame_name>${mp['namespace']}/front_cam_link</frame_name>
        <hack_baseline>0.07</hack_baseline>
        <min_depth>0.001</min_depth>
        <max_depth>3.0</max_depth>
      </plugin>
    </sensor>
  </gazebo>
  <!-- Gazebo ROS 2 plugin for fan control -->
  <!-- <gazebo>
    <plugin name="joint_state_publisher" filename="libgazebo_ros_joint_state_publisher.so">
      <update_rate>100</update_rate>
      <joint_name>fan1_joint</joint_name>
      <joint_name>fan2_joint</joint_name>
      <joint_name>fan3_joint</joint_name>
      <joint_name>fan4_joint</joint_name>
    </plugin>
  </gazebo> -->

  <gazebo>
    <plugin filename="libgazebo_ros2_control.so" name="gazebo_ros2_control">
      <robot_sim_type>gazebo_ros2_control/GazeboSystem</robot_sim_type>
      <parameters>/home/meet/ros2_ws/src/flood_pkg/config/drone.yaml</parameters>
    </plugin>
  </gazebo>


</robot>
