<?xml version="1.0"?>
<robot name="drone_again">

  <!-- Drone body -->
  <link name="base_link">
    <inertial>
      <origin xyz="0.0017017 0.0018936 0.24906" rpy="0 0 0" />
      <mass value="121.76" />
      <inertia ixx="27.393" ixy="0.00020527" ixz="-0.0029529" iyy="28.725" iyz="0.0020718" izz="51.537" />
    </inertial>
    <visual>
      <origin xyz="0 0 0" rpy="0 0 0" />
      <geometry>
        <mesh filename="file://$(find flood_pkg)/meshes/base_link.STL" />
      </geometry>
      <material name="Black">
        <color rgba="0 0 0 1" />
      </material>
    </visual>
    <collision>
      <origin xyz="0 0 0" rpy="0 0 0" />
      <geometry>
        <mesh filename="file://$(find flood_pkg)/meshes/base_link.STL" />
      </geometry>
    </collision>
  </link>

  <!-- Fan 1 -->
  <link name="fan1">
    <inertial>
      <origin xyz="-6.705E-09 1.085E-09 -0.00011192" rpy="0 0 0" />
      <mass value="1.0374" />
      <inertia ixx="0.077898" ixy="0.0029518" ixz="3.7948E-09" iyy="0.0019155" iyz="5.4443E-09" izz="0.079419" />
    </inertial>
    <visual>
      <origin xyz="0 0 0" rpy="0 0 0" />
      <geometry>
        <mesh filename="file://$(find flood_pkg)/meshes/fan1.STL" />
      </geometry>
      <material name="Red">
        <color rgba="1 0 0 1" />
      </material>
    </visual>
    <collision>
      <origin xyz="0 0 0" rpy="0 0 0" />
      <geometry>
        <mesh filename="file://$(find flood_pkg)/meshes/fan1.STL" />
      </geometry>
    </collision>
  </link>
  <joint name="fan1_joint" type="continuous">
    <origin xyz="-0.8465 -0.84715 0.36599" rpy="0 0 0" />
    <parent link="drone_body" />
    <child link="fan1" />
    <axis xyz="0 0 1" />
  </joint>

  <!-- Fan 2 -->
  <link name="fan2">
    <inertial>
      <origin xyz="-6.705E-09 1.085E-09 -0.00011192" rpy="0 0 0" />
      <mass value="1.0374" />
      <inertia ixx="0.077898" ixy="0.0029518" ixz="3.7935E-09" iyy="0.0019155" iyz="5.4394E-09" izz="0.079419" />
    </inertial>
    <visual>
      <origin xyz="0 0 0" rpy="0 0 0" />
      <geometry>
        <mesh filename="file://$(find flood_pkg)/meshes/fan2.STL" />
      </geometry>
      <material name="Red">
        <color rgba="1 0 0 1" />
      </material>
    </visual>
    <collision>
      <origin xyz="0 0 0" rpy="0 0 0" />
      <geometry>
        <mesh filename="file://$(find flood_pkg)/meshes/fan2.STL" />
      </geometry>
    </collision>
  </link>
  <joint name="fan2_joint" type="continuous">
    <origin xyz="-0.8465 0.84991 0.36599" rpy="0 0 0" />
    <parent link="drone_body" />
    <child link="fan2" />
    <axis xyz="0 0 1" />
  </joint>

  <!-- Fan 3 -->
  <link name="fan3">
    <inertial>
      <origin xyz="-6.705E-09 1.085E-09 -0.00011192" rpy="0 0 0" />
      <mass value="1.0374" />
      <inertia ixx="0.077898" ixy="0.0029518" ixz="3.7935E-09" iyy="0.0019155" iyz="5.4394E-09" izz="0.079419" />
    </inertial>
    <visual>
      <origin xyz="0 0 0" rpy="0 0 0" />
      <geometry>
        <mesh filename="file://$(find flood_pkg)/meshes/fan3.STL" />
      </geometry>
      <material name="Red">
        <color rgba="1 0 0 1" />
      </material>
    </visual>
    <collision>
      <origin xyz="0 0 0" rpy="0 0 0" />
      <geometry>
        <mesh filename="file://$(find flood_pkg)/meshes/fan3.STL" />
      </geometry>
    </collision>
  </link>
  <joint name="fan3_joint" type="continuous">
    <origin xyz="0.85056 0.84991 0.36599" rpy="0 0 0" />
    <parent link="drone_body" />
    <child link="fan3" />
    <axis xyz="0 0 1" />
  </joint>

  <!-- Fan 4 -->
  <link name="fan4">
    <inertial>
      <origin xyz="-6.705E-09 1.085E-09 -0.00011192" rpy="0 0 0" />
      <mass value="1.0374" />
      <inertia ixx="0.077898" ixy="0.0029518" ixz="3.8019E-09" iyy="0.0019155" iyz="5.4639E-09" izz="0.079419" />
    </inertial>
    <visual>
      <origin xyz="0 0 0" rpy="0 0 0" />
      <geometry>
        <mesh filename="file://$(find flood_pkg)/meshes/fan4.STL" />
      </geometry>
      <material name="Red">
        <color rgba="1 0 0 1" />
      </material>
    </visual>
    <collision>
      <origin xyz="0 0 0" rpy="0 0 0" />
      <geometry>
        <mesh filename="file://$(find flood_pkg)/meshes/fan4.STL" />
      </geometry>
    </collision>
  </link>
  <joint name="fan4_joint" type="continuous">
    <origin xyz="0.85056 -0.84715 0.36599" rpy="0 0 0" />
    <parent link="drone_body" />
    <child link="fan4" />
    <axis xyz="0 0 1" />
  </joint>

  <!-- Gazebo material definitions -->

  <gazebo reference="drone_body">
    <material>Gazebo/Black</material>
    <selfCollide>true</selfCollide>
    <gravity>true</gravity>
  </gazebo>

  <gazebo reference="fan1">
    <material>Gazebo/Red</material>
    <selfCollide>true</selfCollide>
    <gravity>true</gravity>
  </gazebo>

  <gazebo reference="fan2">
    <material>Gazebo/Red</material>
    <selfCollide>true</selfCollide>
    <gravity>true</gravity>
  </gazebo>

  <gazebo reference="fan3">
    <material>Gazebo/Red</material>
    <selfCollide>true</selfCollide>
    <gravity>true</gravity>
  </gazebo>

  <gazebo reference="fan4">
    <material>Gazebo/Red</material>
    <selfCollide>true</selfCollide>
    <gravity>true</gravity>
  </gazebo>

</robot>